2018-12-12T17:53:45|CRITICAL|root|Unhandled exception:Traceback (most recent call last):
  File "C:\ProgramData\Anaconda3\lib\site-packages\ScopeFoundry\hardware.py", line 208, in enable_connection
    raise err
  File "C:\ProgramData\Anaconda3\lib\site-packages\ScopeFoundry\hardware.py", line 204, in enable_connection
    self.connect()
  File "E:\LabPrograms\Python\PI_stage\pi_stage_HW.py", line 54, in connect
    self.gcs = GCSDevice('M-405.CG')#gcsdll=dll_path)
  File "C:\ProgramData\Anaconda3\lib\site-packages\pipython-1.3.4.17-py3.6.egg\pipython\gcsdevice.py", line 21, in __init__
    self.__interface = GCSDll(devname, gcsdll)
  File "C:\ProgramData\Anaconda3\lib\site-packages\pipython-1.3.4.17-py3.6.egg\pipython\interfaces\gcsdll.py", line 132, in __init__
    dllname = dllname or get_dll_name(devname)
  File "C:\ProgramData\Anaconda3\lib\site-packages\pipython-1.3.4.17-py3.6.egg\pipython\interfaces\gcsdll.py", line 56, in get_dll_name
    raise NotImplementedError('unknown device name %r' % devname)
NotImplementedError: unknown device name 'M-405'

