2018-12-19T12:22:20|CRITICAL|root|Unhandled exception:Traceback (most recent call last):
  File "C:\ProgramData\Anaconda3\lib\site-packages\ScopeFoundry\hardware.py", line 160, in <lambda>
    op_button.clicked.connect(lambda checked, f=op_func: f())
  File "E:\LabPrograms\Python\PI_stage\pi_stage_HW_test.py", line 164, in set_home
    self.gcs.DFH(self.gcs.axes)
AttributeError: 'PIStage' object has no attribute 'gcs'

2018-12-19T12:22:20|CRITICAL|root|Unhandled exception:Traceback (most recent call last):
  File "C:\ProgramData\Anaconda3\lib\site-packages\ScopeFoundry\hardware.py", line 160, in <lambda>
    op_button.clicked.connect(lambda checked, f=op_func: f())
  File "E:\LabPrograms\Python\PI_stage\pi_stage_HW_test.py", line 164, in set_home
    self.gcs.DFH(self.gcs.axes)
AttributeError: 'PIStage' object has no attribute 'gcs'

2018-12-19T12:22:21|CRITICAL|root|Unhandled exception:Traceback (most recent call last):
  File "C:\ProgramData\Anaconda3\lib\site-packages\ScopeFoundry\hardware.py", line 160, in <lambda>
    op_button.clicked.connect(lambda checked, f=op_func: f())
  File "E:\LabPrograms\Python\PI_stage\pi_stage_HW_test.py", line 167, in go_home
    self.gcs.GOH(self.gcs.axes)
AttributeError: 'PIStage' object has no attribute 'gcs'

