2018-12-19T15:03:43|CRITICAL|root|Unhandled exception:Traceback (most recent call last):
  File "C:\ProgramData\Anaconda3\lib\site-packages\ScopeFoundry\hardware.py", line 219, in enable_connection
    raise err
  File "C:\ProgramData\Anaconda3\lib\site-packages\ScopeFoundry\hardware.py", line 212, in enable_connection
    self.disconnect()
  File "E:\LabPrograms\Python\PI_stage\pi_stage_HW_test.py", line 135, in disconnect
    self.gcs.STP()
  File "C:\ProgramData\Anaconda3\lib\site-packages\pipython-1.3.4.17-py3.6.egg\pipython\gcscommands.py", line 2042, in STP
    self.__msgs.send(cmdstr)
  File "C:\ProgramData\Anaconda3\lib\site-packages\pipython-1.3.4.17-py3.6.egg\pipython\gcsmessages.py", line 120, in send
    self.__checkerror(senderr=not self.__embederr)
  File "C:\ProgramData\Anaconda3\lib\site-packages\pipython-1.3.4.17-py3.6.egg\pipython\gcsmessages.py", line 278, in __checkerror
    raise exc  # Raising NoneType while only classes or instances are allowed pylint: disable=E0702
pipython.gcserror.GCSError: Controller was stopped by command (10)

2018-12-19T15:03:55|CRITICAL|root|Unhandled exception:Traceback (most recent call last):
  File "C:\ProgramData\Anaconda3\lib\site-packages\ScopeFoundry\hardware.py", line 204, in enable_connection
    self.connect()
  File "E:\LabPrograms\Python\PI_stage\pi_stage_HW_test.py", line 64, in connect
    self.gcs.ConnectRS232(comport=8, baudrate=38400)
  File "C:\ProgramData\Anaconda3\lib\site-packages\pipython-1.3.4.17-py3.6.egg\pipython\gcsdevice.py", line 106, in ConnectRS232
    self.__interface.ConnectRS232(comport, baudrate)
  File "C:\ProgramData\Anaconda3\lib\site-packages\pipython-1.3.4.17-py3.6.egg\pipython\interfaces\gcsdll.py", line 325, in ConnectRS232
    raise GCSError(self.__error)
pipython.gcserror.GCSError: There is no interface or DLL handle with the given ID (-9)

During handling of the above exception, another exception occurred:

Traceback (most recent call last):
  File "C:\ProgramData\Anaconda3\lib\site-packages\ScopeFoundry\hardware.py", line 219, in enable_connection
    raise err
  File "C:\ProgramData\Anaconda3\lib\site-packages\ScopeFoundry\hardware.py", line 212, in enable_connection
    self.disconnect()
  File "E:\LabPrograms\Python\PI_stage\pi_stage_HW_test.py", line 134, in disconnect
    if list(self.gcs.IsMoving(self.gcs.axes))[0]:
  File "C:\ProgramData\Anaconda3\lib\site-packages\pipython-1.3.4.17-py3.6.egg\pipython\gcscommands.py", line 480, in axes
    self.__axes = self.qSAI()
  File "C:\ProgramData\Anaconda3\lib\site-packages\pipython-1.3.4.17-py3.6.egg\pipython\gcscommands.py", line 970, in qSAI
    answer = self.__msgs.read('SAI?')
  File "C:\ProgramData\Anaconda3\lib\site-packages\pipython-1.3.4.17-py3.6.egg\pipython\gcsmessages.py", line 136, in read
    while self.__interface.answersize:
  File "C:\ProgramData\Anaconda3\lib\site-packages\pipython-1.3.4.17-py3.6.egg\pipython\interfaces\gcsdll.py", line 164, in answersize
    raise GCSError(self.__error)
pipython.gcserror.GCSError: There is no interface or DLL handle with the given ID (-9)

2018-12-19T15:03:55|CRITICAL|root|Unhandled exception:Traceback (most recent call last):
  File "C:\ProgramData\Anaconda3\lib\site-packages\ScopeFoundry\hardware.py", line 208, in enable_connection
    raise err
  File "C:\ProgramData\Anaconda3\lib\site-packages\ScopeFoundry\hardware.py", line 204, in enable_connection
    self.connect()
  File "E:\LabPrograms\Python\PI_stage\pi_stage_HW_test.py", line 64, in connect
    self.gcs.ConnectRS232(comport=8, baudrate=38400)
  File "C:\ProgramData\Anaconda3\lib\site-packages\pipython-1.3.4.17-py3.6.egg\pipython\gcsdevice.py", line 106, in ConnectRS232
    self.__interface.ConnectRS232(comport, baudrate)
  File "C:\ProgramData\Anaconda3\lib\site-packages\pipython-1.3.4.17-py3.6.egg\pipython\interfaces\gcsdll.py", line 325, in ConnectRS232
    raise GCSError(self.__error)
pipython.gcserror.GCSError: There is no interface or DLL handle with the given ID (-9)

