2018-12-13T12:49:51|WARNING|LoggedQuantity|rangemin read_from_hardware called when not connected to hardware
2018-12-13T12:49:51|CRITICAL|root|Unhandled exception:Traceback (most recent call last):
  File "C:\ProgramData\Anaconda3\lib\site-packages\ScopeFoundry\hardware.py", line 208, in enable_connection
    raise err
  File "C:\ProgramData\Anaconda3\lib\site-packages\ScopeFoundry\hardware.py", line 204, in enable_connection
    self.connect()
  File "E:\LabPrograms\Python\PI_stage\pi_stage_HW_test.py", line 65, in connect
    self.rangemax.read_from_hardware()
  File "C:\ProgramData\Anaconda3\lib\site-packages\ScopeFoundry\logged_quantity.py", line 161, in read_from_hardware
    val = self.hardware_read_func()
TypeError: 'float' object is not callable

