2018-12-13T15:28:20|CRITICAL|root|Unhandled exception:Traceback (most recent call last):
  File "C:\ProgramData\Anaconda3\lib\site-packages\ScopeFoundry\hardware.py", line 219, in enable_connection
    raise err
  File "C:\ProgramData\Anaconda3\lib\site-packages\ScopeFoundry\hardware.py", line 212, in enable_connection
    self.disconnect()
  File "E:\LabPrograms\Python\PI_stage\pi_stage_HW_test.py", line 118, in disconnect
    self.gcs.MOV(1, self.settings.reference_switch)
AttributeError: 'PIStage' object has no attribute 'gcs'

2018-12-13T15:28:21|CRITICAL|root|Unhandled exception:Traceback (most recent call last):
  File "C:\ProgramData\Anaconda3\lib\site-packages\ScopeFoundry\hardware.py", line 204, in enable_connection
    self.connect()
  File "E:\LabPrograms\Python\PI_stage\pi_stage_HW_test.py", line 59, in connect
    self.gcs.ConnectRS232(comport=8, baudrate=38400)
  File "C:\ProgramData\Anaconda3\lib\site-packages\pipython-1.3.4.17-py3.6.egg\pipython\gcsdevice.py", line 106, in ConnectRS232
    self.__interface.ConnectRS232(comport, baudrate)
  File "C:\ProgramData\Anaconda3\lib\site-packages\pipython-1.3.4.17-py3.6.egg\pipython\interfaces\gcsdll.py", line 325, in ConnectRS232
    raise GCSError(self.__error)
pipython.gcserror.GCSError: There is no interface or DLL handle with the given ID (-9)

During handling of the above exception, another exception occurred:

Traceback (most recent call last):
  File "C:\ProgramData\Anaconda3\lib\site-packages\ScopeFoundry\hardware.py", line 219, in enable_connection
    raise err
  File "C:\ProgramData\Anaconda3\lib\site-packages\ScopeFoundry\hardware.py", line 212, in enable_connection
    self.disconnect()
  File "E:\LabPrograms\Python\PI_stage\pi_stage_HW_test.py", line 118, in disconnect
    self.gcs.MOV(1, self.settings.reference_switch)
  File "C:\ProgramData\Anaconda3\lib\site-packages\pipython-1.3.4.17-py3.6.egg\pipython\gcscommands.py", line 3106, in MOV
    self.__msgs.send(cmdstr)
  File "C:\ProgramData\Anaconda3\lib\site-packages\pipython-1.3.4.17-py3.6.egg\pipython\gcsmessages.py", line 119, in send
    self.__send(tosend)
  File "C:\ProgramData\Anaconda3\lib\site-packages\pipython-1.3.4.17-py3.6.egg\pipython\gcsmessages.py", line 164, in __send
    self.__interface.send(tosend)
  File "C:\ProgramData\Anaconda3\lib\site-packages\pipython-1.3.4.17-py3.6.egg\pipython\interfaces\gcsdll.py", line 157, in send
    raise GCSError(self.__error)
pipython.gcserror.GCSError: There is no interface or DLL handle with the given ID (-9)

2018-12-13T15:28:21|CRITICAL|root|Unhandled exception:Traceback (most recent call last):
  File "C:\ProgramData\Anaconda3\lib\site-packages\ScopeFoundry\hardware.py", line 208, in enable_connection
    raise err
  File "C:\ProgramData\Anaconda3\lib\site-packages\ScopeFoundry\hardware.py", line 204, in enable_connection
    self.connect()
  File "E:\LabPrograms\Python\PI_stage\pi_stage_HW_test.py", line 59, in connect
    self.gcs.ConnectRS232(comport=8, baudrate=38400)
  File "C:\ProgramData\Anaconda3\lib\site-packages\pipython-1.3.4.17-py3.6.egg\pipython\gcsdevice.py", line 106, in ConnectRS232
    self.__interface.ConnectRS232(comport, baudrate)
  File "C:\ProgramData\Anaconda3\lib\site-packages\pipython-1.3.4.17-py3.6.egg\pipython\interfaces\gcsdll.py", line 325, in ConnectRS232
    raise GCSError(self.__error)
pipython.gcserror.GCSError: There is no interface or DLL handle with the given ID (-9)

2018-12-13T15:28:30|CRITICAL|root|Unhandled exception:Traceback (most recent call last):
  File "C:\ProgramData\Anaconda3\lib\site-packages\ScopeFoundry\hardware.py", line 204, in enable_connection
    self.connect()
  File "E:\LabPrograms\Python\PI_stage\pi_stage_HW_test.py", line 59, in connect
    self.gcs.ConnectRS232(comport=8, baudrate=38400)
  File "C:\ProgramData\Anaconda3\lib\site-packages\pipython-1.3.4.17-py3.6.egg\pipython\gcsdevice.py", line 106, in ConnectRS232
    self.__interface.ConnectRS232(comport, baudrate)
  File "C:\ProgramData\Anaconda3\lib\site-packages\pipython-1.3.4.17-py3.6.egg\pipython\interfaces\gcsdll.py", line 325, in ConnectRS232
    raise GCSError(self.__error)
pipython.gcserror.GCSError: There is no interface or DLL handle with the given ID (-9)

During handling of the above exception, another exception occurred:

Traceback (most recent call last):
  File "C:\ProgramData\Anaconda3\lib\site-packages\ScopeFoundry\hardware.py", line 219, in enable_connection
    raise err
  File "C:\ProgramData\Anaconda3\lib\site-packages\ScopeFoundry\hardware.py", line 212, in enable_connection
    self.disconnect()
  File "E:\LabPrograms\Python\PI_stage\pi_stage_HW_test.py", line 118, in disconnect
    self.gcs.MOV(1, self.settings.reference_switch)
  File "C:\ProgramData\Anaconda3\lib\site-packages\pipython-1.3.4.17-py3.6.egg\pipython\gcscommands.py", line 3106, in MOV
    self.__msgs.send(cmdstr)
  File "C:\ProgramData\Anaconda3\lib\site-packages\pipython-1.3.4.17-py3.6.egg\pipython\gcsmessages.py", line 119, in send
    self.__send(tosend)
  File "C:\ProgramData\Anaconda3\lib\site-packages\pipython-1.3.4.17-py3.6.egg\pipython\gcsmessages.py", line 164, in __send
    self.__interface.send(tosend)
  File "C:\ProgramData\Anaconda3\lib\site-packages\pipython-1.3.4.17-py3.6.egg\pipython\interfaces\gcsdll.py", line 157, in send
    raise GCSError(self.__error)
pipython.gcserror.GCSError: There is no interface or DLL handle with the given ID (-9)

2018-12-13T15:28:30|CRITICAL|root|Unhandled exception:Traceback (most recent call last):
  File "C:\ProgramData\Anaconda3\lib\site-packages\ScopeFoundry\hardware.py", line 208, in enable_connection
    raise err
  File "C:\ProgramData\Anaconda3\lib\site-packages\ScopeFoundry\hardware.py", line 204, in enable_connection
    self.connect()
  File "E:\LabPrograms\Python\PI_stage\pi_stage_HW_test.py", line 59, in connect
    self.gcs.ConnectRS232(comport=8, baudrate=38400)
  File "C:\ProgramData\Anaconda3\lib\site-packages\pipython-1.3.4.17-py3.6.egg\pipython\gcsdevice.py", line 106, in ConnectRS232
    self.__interface.ConnectRS232(comport, baudrate)
  File "C:\ProgramData\Anaconda3\lib\site-packages\pipython-1.3.4.17-py3.6.egg\pipython\interfaces\gcsdll.py", line 325, in ConnectRS232
    raise GCSError(self.__error)
pipython.gcserror.GCSError: There is no interface or DLL handle with the given ID (-9)

