2018-12-19T16:24:19|CRITICAL|root|Unhandled exception:Traceback (most recent call last):
  File "C:\ProgramData\Anaconda3\lib\site-packages\ScopeFoundry\hardware.py", line 160, in <lambda>
    op_button.clicked.connect(lambda checked, f=op_func: f())
  File "E:\LabPrograms\Python\PI_stage\pi_stage_HW_test.py", line 173, in move_relative
    self.gcs.MVR(self.gcs.axes, self.settings.x_relative_target_step)
  File "C:\ProgramData\Anaconda3\lib\site-packages\pipython-1.3.4.17-py3.6.egg\pipython\gcscommands.py", line 3714, in MVR
    self.__msgs.send(cmdstr)
  File "C:\ProgramData\Anaconda3\lib\site-packages\pipython-1.3.4.17-py3.6.egg\pipython\gcsmessages.py", line 120, in send
    self.__checkerror(senderr=not self.__embederr)
  File "C:\ProgramData\Anaconda3\lib\site-packages\pipython-1.3.4.17-py3.6.egg\pipython\gcsmessages.py", line 278, in __checkerror
    raise exc  # Raising NoneType while only classes or instances are allowed pylint: disable=E0702
pipython.gcserror.GCSError: Incorrect number of parameters (24)

