2018-12-17T10:37:46|CRITICAL|root|Unhandled exception:Traceback (most recent call last):
  File "C:\ProgramData\Anaconda3\lib\site-packages\ScopeFoundry\logged_quantity.py", line 241, in update_value
    self.hardware_set_func(self.val)
  File "E:\LabPrograms\Python\PI_stage\pi_stage_HW_test.py", line 91, in <lambda>
    write_func = lambda new_target, n=ax_num: self.gcs.MOV(n, new_target)
  File "C:\ProgramData\Anaconda3\lib\site-packages\pipython-1.3.4.17-py3.6.egg\pipython\gcscommands.py", line 3106, in MOV
    self.__msgs.send(cmdstr)
  File "C:\ProgramData\Anaconda3\lib\site-packages\pipython-1.3.4.17-py3.6.egg\pipython\gcsmessages.py", line 120, in send
    self.__checkerror(senderr=not self.__embederr)
  File "C:\ProgramData\Anaconda3\lib\site-packages\pipython-1.3.4.17-py3.6.egg\pipython\gcsmessages.py", line 278, in __checkerror
    raise exc  # Raising NoneType while only classes or instances are allowed pylint: disable=E0702
pipython.gcserror.GCSError: Position out of limits (7)

2018-12-17T10:37:57|CRITICAL|root|Unhandled exception:Traceback (most recent call last):
  File "C:\ProgramData\Anaconda3\lib\site-packages\ScopeFoundry\logged_quantity.py", line 241, in update_value
    self.hardware_set_func(self.val)
  File "E:\LabPrograms\Python\PI_stage\pi_stage_HW_test.py", line 91, in <lambda>
    write_func = lambda new_target, n=ax_num: self.gcs.MOV(n, new_target)
  File "C:\ProgramData\Anaconda3\lib\site-packages\pipython-1.3.4.17-py3.6.egg\pipython\gcscommands.py", line 3106, in MOV
    self.__msgs.send(cmdstr)
  File "C:\ProgramData\Anaconda3\lib\site-packages\pipython-1.3.4.17-py3.6.egg\pipython\gcsmessages.py", line 120, in send
    self.__checkerror(senderr=not self.__embederr)
  File "C:\ProgramData\Anaconda3\lib\site-packages\pipython-1.3.4.17-py3.6.egg\pipython\gcsmessages.py", line 278, in __checkerror
    raise exc  # Raising NoneType while only classes or instances are allowed pylint: disable=E0702
pipython.gcserror.GCSError: Parameter syntax error (1)

2018-12-17T10:39:30|CRITICAL|root|Unhandled exception:Traceback (most recent call last):
  File "C:\ProgramData\Anaconda3\lib\site-packages\ScopeFoundry\hardware.py", line 208, in enable_connection
    raise err
  File "C:\ProgramData\Anaconda3\lib\site-packages\ScopeFoundry\hardware.py", line 204, in enable_connection
    self.connect()
  File "E:\LabPrograms\Python\PI_stage\pi_stage_HW_test.py", line 64, in connect
    pitools.startup(self.gcs, stages=S.stage.val, refmode=S.ref_mode.val)
  File "C:\ProgramData\Anaconda3\lib\site-packages\pipython-1.3.4.17-py3.6.egg\pipython\pitools.py", line 87, in startup
    waitontarget(pidevice, axes=referencedaxes)
  File "C:\ProgramData\Anaconda3\lib\site-packages\pipython-1.3.4.17-py3.6.egg\pipython\pitools.py", line 178, in waitontarget
    waitonready(pidevice, timeout, predelay)
  File "C:\ProgramData\Anaconda3\lib\site-packages\pipython-1.3.4.17-py3.6.egg\pipython\pitools.py", line 162, in waitonready
    raise SystemError('waitonready() timed out after %.1f seconds' % timeout)
SystemError: waitonready() timed out after 60.0 seconds

