2018-12-17T09:37:33|CRITICAL|root|Unhandled exception:Traceback (most recent call last):
  File "C:\ProgramData\Anaconda3\lib\site-packages\ScopeFoundry\hardware.py", line 208, in enable_connection
    raise err
  File "C:\ProgramData\Anaconda3\lib\site-packages\ScopeFoundry\hardware.py", line 204, in enable_connection
    self.connect()
  File "E:\LabPrograms\Python\PI_stage\pi_stage_HW_test.py", line 61, in connect
    self.gcs.ConnectRS232(comport=8, baudrate=38400)
  File "C:\ProgramData\Anaconda3\lib\site-packages\pipython-1.3.4.17-py3.6.egg\pipython\gcsdevice.py", line 106, in ConnectRS232
    self.__interface.ConnectRS232(comport, baudrate)
  File "C:\ProgramData\Anaconda3\lib\site-packages\pipython-1.3.4.17-py3.6.egg\pipython\interfaces\gcsdll.py", line 325, in ConnectRS232
    raise GCSError(self.__error)
pipython.gcserror.GCSError: There is no interface or DLL handle with the given ID (-9)

