2018-12-17T11:20:38|CRITICAL|root|Unhandled exception:Traceback (most recent call last):
  File "C:\ProgramData\Anaconda3\lib\site-packages\ScopeFoundry\hardware.py", line 219, in enable_connection
    raise err
  File "C:\ProgramData\Anaconda3\lib\site-packages\ScopeFoundry\hardware.py", line 212, in enable_connection
    self.disconnect()
  File "E:\LabPrograms\Python\PI_stage\pi_stage_HW_test.py", line 128, in disconnect
    if not self.gcs.IsMoving(self.gcs.axes):
AttributeError: 'PIStage' object has no attribute 'gcs'

