2018-12-13T11:10:40|CRITICAL|root|Unhandled exception:Traceback (most recent call last):
  File "C:\ProgramData\Anaconda3\lib\site-packages\ScopeFoundry\hardware.py", line 208, in enable_connection
    raise err
  File "C:\ProgramData\Anaconda3\lib\site-packages\ScopeFoundry\hardware.py", line 204, in enable_connection
    self.connect()
  File "E:\LabPrograms\Python\PI_stage\pi_stage_HW_test.py", line 59, in connect
    pitools.startup(self.gcs, stages=STAGES, refmode=REFMODE)
  File "C:\ProgramData\Anaconda3\lib\site-packages\pipython-1.3.4.17-py3.6.egg\pipython\pitools.py", line 87, in startup
    waitontarget(pidevice, axes=referencedaxes)
  File "C:\ProgramData\Anaconda3\lib\site-packages\pipython-1.3.4.17-py3.6.egg\pipython\pitools.py", line 178, in waitontarget
    waitonready(pidevice, timeout, predelay)
  File "C:\ProgramData\Anaconda3\lib\site-packages\pipython-1.3.4.17-py3.6.egg\pipython\pitools.py", line 162, in waitonready
    raise SystemError('waitonready() timed out after %.1f seconds' % timeout)
SystemError: waitonready() timed out after 60.0 seconds

