2018-12-19T15:54:42|CRITICAL|root|Unhandled exception:Traceback (most recent call last):
  File "C:\ProgramData\Anaconda3\lib\site-packages\ScopeFoundry\hardware.py", line 208, in enable_connection
    raise err
  File "C:\ProgramData\Anaconda3\lib\site-packages\ScopeFoundry\hardware.py", line 204, in enable_connection
    self.connect()
  File "E:\LabPrograms\Python\PI_stage\pi_stage_HW_test.py", line 108, in connect
    lq.read_from_hardware()
  File "C:\ProgramData\Anaconda3\lib\site-packages\ScopeFoundry\logged_quantity.py", line 161, in read_from_hardware
    val = self.hardware_read_func()
  File "E:\LabPrograms\Python\PI_stage\pi_stage_HW_test.py", line 104, in <lambda>
    read_func  = lambda n=ax_num: self.gcs.qMVR()[str(n)],
AttributeError: 'GCSDevice' object has no attribute 'qMVR'

