2018-12-13T11:58:16|CRITICAL|root|Unhandled exception:Traceback (most recent call last):
  File "C:\ProgramData\Anaconda3\lib\site-packages\ScopeFoundry\hardware.py", line 208, in enable_connection
    raise err
  File "C:\ProgramData\Anaconda3\lib\site-packages\ScopeFoundry\hardware.py", line 204, in enable_connection
    self.connect()
  File "E:\LabPrograms\Python\PI_stage\pi_stage_HW_test.py", line 64, in connect
    self.rangemin.read_from_hardware()
  File "C:\ProgramData\Anaconda3\lib\site-packages\ScopeFoundry\logged_quantity.py", line 162, in read_from_hardware
    self.update_value(new_val=val, update_hardware=False, send_signal=send_signal)
  File "C:\ProgramData\Anaconda3\lib\site-packages\ScopeFoundry\logged_quantity.py", line 223, in update_value
    new_val = self.coerce_to_type(new_val)
  File "C:\ProgramData\Anaconda3\lib\site-packages\ScopeFoundry\logged_quantity.py", line 135, in coerce_to_type
    return self.dtype(x)
TypeError: float() argument must be a string or a number, not 'odict_values'

