2018-12-14T10:21:40|CRITICAL|root|Unhandled exception:Traceback (most recent call last):
  File "C:\ProgramData\Anaconda3\lib\site-packages\ScopeFoundry\hardware.py", line 208, in enable_connection
    raise err
  File "C:\ProgramData\Anaconda3\lib\site-packages\ScopeFoundry\hardware.py", line 204, in enable_connection
    self.connect()
  File "E:\LabPrograms\Python\PI_stage\pi_stage_HW_test.py", line 65, in connect
    self.gcs.POS(self.gcs.axes,self.gcs.qPOS())
  File "C:\ProgramData\Anaconda3\lib\site-packages\pipython-1.3.4.17-py3.6.egg\pipython\gcscommands.py", line 2258, in POS
    axes, values = getitemsvaluestuple(axes, values)
  File "C:\ProgramData\Anaconda3\lib\site-packages\pipython-1.3.4.17-py3.6.egg\pipython\gcscommands.py", line 140, in getitemsvaluestuple
    values = getitemslist(values)
  File "C:\ProgramData\Anaconda3\lib\site-packages\pipython-1.3.4.17-py3.6.egg\pipython\gcscommands.py", line 117, in getitemslist
    raise TypeError('parameter type mismatch: %r' % items)
TypeError: parameter type mismatch: OrderedDict([('1', 25.000007)])

