2018-12-13T12:43:08|CRITICAL|root|Unhandled exception:Traceback (most recent call last):
  File "C:\ProgramData\Anaconda3\lib\site-packages\ScopeFoundry\hardware.py", line 208, in enable_connection
    raise err
  File "C:\ProgramData\Anaconda3\lib\site-packages\ScopeFoundry\hardware.py", line 204, in enable_connection
    self.connect()
  File "E:\LabPrograms\Python\PI_stage\pi_stage_HW_test.py", line 61, in connect
    print(float(self.gcs.qTMN().values()))
TypeError: float() argument must be a string or a number, not 'odict_values'

