2018-12-22T16:33:08|WARNING|root|no GCSTranslator path in Windows registry (HKLM\SOFTWARE\PI\GCSTranslator)
2018-12-22T16:33:08|CRITICAL|root|Unhandled exception:Traceback (most recent call last):
  File "C:\Users\aless\Anaconda3\lib\site-packages\ScopeFoundry\hardware.py", line 204, in enable_connection
    self.connect()
  File "C:\Users\aless\eclipse-workspace\PI_Stage-1\pi_stage_HW_test.py", line 82, in connect
    self.gcs.ConnectRS232(comport=8, baudrate=38400) # Serial connection
  File "C:\Users\aless\Anaconda3\lib\site-packages\pipython-1.3.4.17-py3.7.egg\pipython\gcsdevice.py", line 106, in ConnectRS232
    self.__interface.ConnectRS232(comport, baudrate)
  File "C:\Users\aless\Anaconda3\lib\site-packages\pipython-1.3.4.17-py3.7.egg\pipython\interfaces\gcsdll.py", line 323, in ConnectRS232
    self.__id = getattr(self.__handle, self.__prefix + 'ConnectRS232')(ccomport, cbaudrate)
  File "C:\Users\aless\Anaconda3\lib\site-packages\pipython-1.3.4.17-py3.7.egg\pipython\interfaces\gcsdll.py", line 213, in __handle
    raise IOError('%r not found' % self.__dllpath)
OSError: 'C:\\Users\\aless\\eclipse-workspace\\PI_Stage-1\\PI_GCS2_DLL_x64.dll' not found

During handling of the above exception, another exception occurred:

Traceback (most recent call last):
  File "C:\Users\aless\Anaconda3\lib\site-packages\ScopeFoundry\hardware.py", line 219, in enable_connection
    raise err
  File "C:\Users\aless\Anaconda3\lib\site-packages\ScopeFoundry\hardware.py", line 212, in enable_connection
    self.disconnect()
  File "C:\Users\aless\eclipse-workspace\PI_Stage-1\pi_stage_HW_test.py", line 161, in disconnect
    self.gcs.SVO(self.gcs.axes, False) # turn the servo OFF
  File "C:\Users\aless\Anaconda3\lib\site-packages\pipython-1.3.4.17-py3.7.egg\pipython\gcscommands.py", line 480, in axes
    self.__axes = self.qSAI()
  File "C:\Users\aless\Anaconda3\lib\site-packages\pipython-1.3.4.17-py3.7.egg\pipython\gcscommands.py", line 970, in qSAI
    answer = self.__msgs.read('SAI?')
  File "C:\Users\aless\Anaconda3\lib\site-packages\pipython-1.3.4.17-py3.7.egg\pipython\gcsmessages.py", line 136, in read
    while self.__interface.answersize:
  File "C:\Users\aless\Anaconda3\lib\site-packages\pipython-1.3.4.17-py3.7.egg\pipython\interfaces\gcsdll.py", line 163, in answersize
    if not getattr(self.__handle, self.__prefix + 'GcsGetAnswerSize')(self.__id, ctypes.byref(size)):
  File "C:\Users\aless\Anaconda3\lib\site-packages\pipython-1.3.4.17-py3.7.egg\pipython\interfaces\gcsdll.py", line 213, in __handle
    raise IOError('%r not found' % self.__dllpath)
OSError: 'C:\\Users\\aless\\eclipse-workspace\\PI_Stage-1\\PI_GCS2_DLL_x64.dll' not found

2018-12-22T16:33:08|CRITICAL|root|Unhandled exception:Traceback (most recent call last):
  File "C:\Users\aless\Anaconda3\lib\site-packages\ScopeFoundry\hardware.py", line 208, in enable_connection
    raise err
  File "C:\Users\aless\Anaconda3\lib\site-packages\ScopeFoundry\hardware.py", line 204, in enable_connection
    self.connect()
  File "C:\Users\aless\eclipse-workspace\PI_Stage-1\pi_stage_HW_test.py", line 82, in connect
    self.gcs.ConnectRS232(comport=8, baudrate=38400) # Serial connection
  File "C:\Users\aless\Anaconda3\lib\site-packages\pipython-1.3.4.17-py3.7.egg\pipython\gcsdevice.py", line 106, in ConnectRS232
    self.__interface.ConnectRS232(comport, baudrate)
  File "C:\Users\aless\Anaconda3\lib\site-packages\pipython-1.3.4.17-py3.7.egg\pipython\interfaces\gcsdll.py", line 323, in ConnectRS232
    self.__id = getattr(self.__handle, self.__prefix + 'ConnectRS232')(ccomport, cbaudrate)
  File "C:\Users\aless\Anaconda3\lib\site-packages\pipython-1.3.4.17-py3.7.egg\pipython\interfaces\gcsdll.py", line 213, in __handle
    raise IOError('%r not found' % self.__dllpath)
OSError: 'C:\\Users\\aless\\eclipse-workspace\\PI_Stage-1\\PI_GCS2_DLL_x64.dll' not found

